// Create a promise
let promise = new Promise((resolve, reject) => {
    setTimeout(() => {
        let result = 4 + 4;
        resolve(result);
    }, 1000); 
});

//  promise result with try...catch
promise.then(
    // The first argument of .then is a function that handles the resolved value
    result => {
        try {
            console.log('Result:', result);
            throw new Error("error inside .then block");
        } catch (error) {
            throw new Error("Failed to log results: " + error.message);
        }
    })
    .catch((error) => {
        // The .catch block handles any errors that occur during promise execution or in preceding .then blocks
        console.error('Error:', error.message); 
        throw new Error("Failed to log results: " + error.message);
    })
    .finally(() => {
        console.log("Code executed!");
    });
